[2023-06-09T09:07:24.166+0000] {taskinstance.py:1103} INFO - Dependencies all met for dep_context=non-requeueable deps ti=<TaskInstance: applicants.read manual__2023-06-09T09:07:22.355732+00:00 [queued]>
[2023-06-09T09:07:24.176+0000] {taskinstance.py:1103} INFO - Dependencies all met for dep_context=requeueable deps ti=<TaskInstance: applicants.read manual__2023-06-09T09:07:22.355732+00:00 [queued]>
[2023-06-09T09:07:24.177+0000] {taskinstance.py:1308} INFO - Starting attempt 1 of 1
[2023-06-09T09:07:24.205+0000] {taskinstance.py:1327} INFO - Executing <Task(PythonOperator): read> on 2023-06-09 09:07:22.355732+00:00
[2023-06-09T09:07:24.215+0000] {standard_task_runner.py:57} INFO - Started process 1994 to run task
[2023-06-09T09:07:24.218+0000] {standard_task_runner.py:84} INFO - Running: ['***', 'tasks', 'run', 'applicants', 'read', 'manual__2023-06-09T09:07:22.355732+00:00', '--job-id', '4', '--raw', '--subdir', 'DAGS_FOLDER/etl.py', '--cfg-path', '/tmp/tmpch4r6fsq']
[2023-06-09T09:07:24.219+0000] {standard_task_runner.py:85} INFO - Job 4: Subtask read
[2023-06-09T09:07:24.278+0000] {task_command.py:410} INFO - Running <TaskInstance: applicants.read manual__2023-06-09T09:07:22.355732+00:00 [running]> on host 9e894d1b1662
[2023-06-09T09:07:24.371+0000] {taskinstance.py:1547} INFO - Exporting env vars: AIRFLOW_CTX_DAG_OWNER='***' AIRFLOW_CTX_DAG_ID='applicants' AIRFLOW_CTX_TASK_ID='read' AIRFLOW_CTX_EXECUTION_DATE='2023-06-09T09:07:22.355732+00:00' AIRFLOW_CTX_TRY_NUMBER='1' AIRFLOW_CTX_DAG_RUN_ID='manual__2023-06-09T09:07:22.355732+00:00'
[2023-06-09T09:07:24.375+0000] {taskinstance.py:1824} ERROR - Task failed with exception
Traceback (most recent call last):
  File "/home/airflow/.local/lib/python3.7/site-packages/airflow/operators/python.py", line 181, in execute
    return_value = self.execute_callable()
  File "/home/airflow/.local/lib/python3.7/site-packages/airflow/operators/python.py", line 198, in execute_callable
    return self.python_callable(*self.op_args, **self.op_kwargs)
  File "/opt/airflow/dags/etl.py", line 16, in read
    df = pd.read_csv(r"C:\Users\julca\greenfox\otocyon-badass-trial-exam\dataset.csv")
  File "/home/airflow/.local/lib/python3.7/site-packages/pandas/util/_decorators.py", line 311, in wrapper
    return func(*args, **kwargs)
  File "/home/airflow/.local/lib/python3.7/site-packages/pandas/io/parsers/readers.py", line 586, in read_csv
    return _read(filepath_or_buffer, kwds)
  File "/home/airflow/.local/lib/python3.7/site-packages/pandas/io/parsers/readers.py", line 482, in _read
    parser = TextFileReader(filepath_or_buffer, **kwds)
  File "/home/airflow/.local/lib/python3.7/site-packages/pandas/io/parsers/readers.py", line 811, in __init__
    self._engine = self._make_engine(self.engine)
  File "/home/airflow/.local/lib/python3.7/site-packages/pandas/io/parsers/readers.py", line 1040, in _make_engine
    return mapping[engine](self.f, **self.options)  # type: ignore[call-arg]
  File "/home/airflow/.local/lib/python3.7/site-packages/pandas/io/parsers/c_parser_wrapper.py", line 51, in __init__
    self._open_handles(src, kwds)
  File "/home/airflow/.local/lib/python3.7/site-packages/pandas/io/parsers/base_parser.py", line 229, in _open_handles
    errors=kwds.get("encoding_errors", "strict"),
  File "/home/airflow/.local/lib/python3.7/site-packages/pandas/io/common.py", line 707, in get_handle
    newline="",
FileNotFoundError: [Errno 2] No such file or directory: 'C:\\Users\\julca\\greenfox\\otocyon-badass-trial-exam\\dataset.csv'
[2023-06-09T09:07:24.391+0000] {taskinstance.py:1350} INFO - Marking task as FAILED. dag_id=applicants, task_id=read, execution_date=20230609T090722, start_date=20230609T090724, end_date=20230609T090724
[2023-06-09T09:07:24.405+0000] {standard_task_runner.py:109} ERROR - Failed to execute job 4 for task read ([Errno 2] No such file or directory: 'C:\\Users\\julca\\greenfox\\otocyon-badass-trial-exam\\dataset.csv'; 1994)
[2023-06-09T09:07:24.430+0000] {local_task_job_runner.py:225} INFO - Task exited with return code 1
[2023-06-09T09:07:24.453+0000] {taskinstance.py:2651} INFO - 0 downstream tasks scheduled from follow-on schedule check
