[2023-06-09T09:08:37.382+0000] {taskinstance.py:1103} INFO - Dependencies all met for dep_context=non-requeueable deps ti=<TaskInstance: applicants.read manual__2023-06-09T09:08:35.710942+00:00 [queued]>
[2023-06-09T09:08:37.390+0000] {taskinstance.py:1103} INFO - Dependencies all met for dep_context=requeueable deps ti=<TaskInstance: applicants.read manual__2023-06-09T09:08:35.710942+00:00 [queued]>
[2023-06-09T09:08:37.391+0000] {taskinstance.py:1308} INFO - Starting attempt 1 of 1
[2023-06-09T09:08:37.408+0000] {taskinstance.py:1327} INFO - Executing <Task(PythonOperator): read> on 2023-06-09 09:08:35.710942+00:00
[2023-06-09T09:08:37.419+0000] {standard_task_runner.py:57} INFO - Started process 2015 to run task
[2023-06-09T09:08:37.424+0000] {standard_task_runner.py:84} INFO - Running: ['***', 'tasks', 'run', 'applicants', 'read', 'manual__2023-06-09T09:08:35.710942+00:00', '--job-id', '5', '--raw', '--subdir', 'DAGS_FOLDER/etl.py', '--cfg-path', '/tmp/tmp05fwxsgd']
[2023-06-09T09:08:37.425+0000] {standard_task_runner.py:85} INFO - Job 5: Subtask read
[2023-06-09T09:08:37.474+0000] {task_command.py:410} INFO - Running <TaskInstance: applicants.read manual__2023-06-09T09:08:35.710942+00:00 [running]> on host 9e894d1b1662
[2023-06-09T09:08:37.563+0000] {taskinstance.py:1547} INFO - Exporting env vars: AIRFLOW_CTX_DAG_OWNER='***' AIRFLOW_CTX_DAG_ID='applicants' AIRFLOW_CTX_TASK_ID='read' AIRFLOW_CTX_EXECUTION_DATE='2023-06-09T09:08:35.710942+00:00' AIRFLOW_CTX_TRY_NUMBER='1' AIRFLOW_CTX_DAG_RUN_ID='manual__2023-06-09T09:08:35.710942+00:00'
[2023-06-09T09:08:37.564+0000] {taskinstance.py:1824} ERROR - Task failed with exception
Traceback (most recent call last):
  File "/home/airflow/.local/lib/python3.7/site-packages/airflow/operators/python.py", line 181, in execute
    return_value = self.execute_callable()
  File "/home/airflow/.local/lib/python3.7/site-packages/airflow/operators/python.py", line 198, in execute_callable
    return self.python_callable(*self.op_args, **self.op_kwargs)
TypeError: read() missing 1 required positional argument: 'df'
[2023-06-09T09:08:37.571+0000] {taskinstance.py:1350} INFO - Marking task as FAILED. dag_id=applicants, task_id=read, execution_date=20230609T090835, start_date=20230609T090837, end_date=20230609T090837
[2023-06-09T09:08:37.588+0000] {standard_task_runner.py:109} ERROR - Failed to execute job 5 for task read (read() missing 1 required positional argument: 'df'; 2015)
[2023-06-09T09:08:37.635+0000] {local_task_job_runner.py:225} INFO - Task exited with return code 1
[2023-06-09T09:08:37.658+0000] {taskinstance.py:2651} INFO - 0 downstream tasks scheduled from follow-on schedule check
