[2023-06-09T13:06:53.327+0000] {taskinstance.py:1103} INFO - Dependencies all met for dep_context=non-requeueable deps ti=<TaskInstance: applicants.load manual__2023-06-09T13:06:46.301821+00:00 [queued]>
[2023-06-09T13:06:53.338+0000] {taskinstance.py:1103} INFO - Dependencies all met for dep_context=requeueable deps ti=<TaskInstance: applicants.load manual__2023-06-09T13:06:46.301821+00:00 [queued]>
[2023-06-09T13:06:53.339+0000] {taskinstance.py:1308} INFO - Starting attempt 1 of 1
[2023-06-09T13:06:53.360+0000] {taskinstance.py:1327} INFO - Executing <Task(PythonOperator): load> on 2023-06-09 13:06:46.301821+00:00
[2023-06-09T13:06:53.369+0000] {standard_task_runner.py:57} INFO - Started process 6265 to run task
[2023-06-09T13:06:53.372+0000] {standard_task_runner.py:84} INFO - Running: ['***', 'tasks', 'run', 'applicants', 'load', 'manual__2023-06-09T13:06:46.301821+00:00', '--job-id', '25', '--raw', '--subdir', 'DAGS_FOLDER/etl.py', '--cfg-path', '/tmp/tmp0mx00gij']
[2023-06-09T13:06:53.374+0000] {standard_task_runner.py:85} INFO - Job 25: Subtask load
[2023-06-09T13:06:53.435+0000] {task_command.py:410} INFO - Running <TaskInstance: applicants.load manual__2023-06-09T13:06:46.301821+00:00 [running]> on host 9e894d1b1662
[2023-06-09T13:06:53.546+0000] {taskinstance.py:1547} INFO - Exporting env vars: AIRFLOW_CTX_DAG_OWNER='***' AIRFLOW_CTX_DAG_ID='applicants' AIRFLOW_CTX_TASK_ID='load' AIRFLOW_CTX_EXECUTION_DATE='2023-06-09T13:06:46.301821+00:00' AIRFLOW_CTX_TRY_NUMBER='1' AIRFLOW_CTX_DAG_RUN_ID='manual__2023-06-09T13:06:46.301821+00:00'
[2023-06-09T13:06:53.645+0000] {taskinstance.py:1824} ERROR - Task failed with exception
Traceback (most recent call last):
  File "/home/airflow/.local/lib/python3.7/site-packages/airflow/operators/python.py", line 181, in execute
    return_value = self.execute_callable()
  File "/home/airflow/.local/lib/python3.7/site-packages/airflow/operators/python.py", line 198, in execute_callable
    return self.python_callable(*self.op_args, **self.op_kwargs)
  File "/opt/airflow/dags/etl.py", line 48, in load
    cursor = c.cursor()
AttributeError: 'Connection' object has no attribute 'cursor'
[2023-06-09T13:06:53.660+0000] {taskinstance.py:1350} INFO - Marking task as FAILED. dag_id=applicants, task_id=load, execution_date=20230609T130646, start_date=20230609T130653, end_date=20230609T130653
[2023-06-09T13:06:53.676+0000] {standard_task_runner.py:109} ERROR - Failed to execute job 25 for task load ('Connection' object has no attribute 'cursor'; 6265)
[2023-06-09T13:06:53.705+0000] {local_task_job_runner.py:225} INFO - Task exited with return code 1
[2023-06-09T13:06:53.725+0000] {taskinstance.py:2651} INFO - 0 downstream tasks scheduled from follow-on schedule check
