[2023-06-13T14:54:56.518+0000] {taskinstance.py:1103} INFO - Dependencies all met for dep_context=non-requeueable deps ti=<TaskInstance: a_etldag.read_transform manual__2023-06-13T14:54:55.229553+00:00 [queued]>
[2023-06-13T14:54:56.528+0000] {taskinstance.py:1103} INFO - Dependencies all met for dep_context=requeueable deps ti=<TaskInstance: a_etldag.read_transform manual__2023-06-13T14:54:55.229553+00:00 [queued]>
[2023-06-13T14:54:56.529+0000] {taskinstance.py:1308} INFO - Starting attempt 1 of 1
[2023-06-13T14:54:56.547+0000] {taskinstance.py:1327} INFO - Executing <Task(PythonOperator): read_transform> on 2023-06-13 14:54:55.229553+00:00
[2023-06-13T14:54:56.552+0000] {standard_task_runner.py:57} INFO - Started process 4185 to run task
[2023-06-13T14:54:56.555+0000] {standard_task_runner.py:84} INFO - Running: ['***', 'tasks', 'run', 'a_etldag', 'read_transform', 'manual__2023-06-13T14:54:55.229553+00:00', '--job-id', '115', '--raw', '--subdir', 'DAGS_FOLDER/etl.py', '--cfg-path', '/tmp/tmpava1x9a2']
[2023-06-13T14:54:56.556+0000] {standard_task_runner.py:85} INFO - Job 115: Subtask read_transform
[2023-06-13T14:54:56.630+0000] {task_command.py:410} INFO - Running <TaskInstance: a_etldag.read_transform manual__2023-06-13T14:54:55.229553+00:00 [running]> on host 9e894d1b1662
[2023-06-13T14:54:56.722+0000] {taskinstance.py:1547} INFO - Exporting env vars: AIRFLOW_CTX_DAG_OWNER='***' AIRFLOW_CTX_DAG_ID='a_etldag' AIRFLOW_CTX_TASK_ID='read_transform' AIRFLOW_CTX_EXECUTION_DATE='2023-06-13T14:54:55.229553+00:00' AIRFLOW_CTX_TRY_NUMBER='1' AIRFLOW_CTX_DAG_RUN_ID='manual__2023-06-13T14:54:55.229553+00:00'
[2023-06-13T14:54:56.850+0000] {taskinstance.py:1824} ERROR - Task failed with exception
Traceback (most recent call last):
  File "/home/airflow/.local/lib/python3.7/site-packages/pandas/core/indexes/base.py", line 3361, in get_loc
    return self._engine.get_loc(casted_key)
  File "pandas/_libs/index.pyx", line 76, in pandas._libs.index.IndexEngine.get_loc
  File "pandas/_libs/index.pyx", line 108, in pandas._libs.index.IndexEngine.get_loc
  File "pandas/_libs/hashtable_class_helper.pxi", line 5198, in pandas._libs.hashtable.PyObjectHashTable.get_item
  File "pandas/_libs/hashtable_class_helper.pxi", line 5206, in pandas._libs.hashtable.PyObjectHashTable.get_item
KeyError: 'class_id'

The above exception was the direct cause of the following exception:

Traceback (most recent call last):
  File "/home/airflow/.local/lib/python3.7/site-packages/airflow/operators/python.py", line 181, in execute
    return_value = self.execute_callable()
  File "/home/airflow/.local/lib/python3.7/site-packages/airflow/operators/python.py", line 198, in execute_callable
    return self.python_callable(*self.op_args, **self.op_kwargs)
  File "/opt/airflow/dags/etl.py", line 32, in read_transform
    df['class_id'] = np.where(df['class_id']=='Panthera', 1, 2)
  File "/home/airflow/.local/lib/python3.7/site-packages/pandas/core/frame.py", line 3458, in __getitem__
    indexer = self.columns.get_loc(key)
  File "/home/airflow/.local/lib/python3.7/site-packages/pandas/core/indexes/base.py", line 3363, in get_loc
    raise KeyError(key) from err
KeyError: 'class_id'
[2023-06-13T14:54:56.869+0000] {taskinstance.py:1350} INFO - Marking task as FAILED. dag_id=a_etldag, task_id=read_transform, execution_date=20230613T145455, start_date=20230613T145456, end_date=20230613T145456
[2023-06-13T14:54:56.883+0000] {standard_task_runner.py:109} ERROR - Failed to execute job 115 for task read_transform ('class_id'; 4185)
[2023-06-13T14:54:56.928+0000] {local_task_job_runner.py:225} INFO - Task exited with return code 1
[2023-06-13T14:54:56.950+0000] {taskinstance.py:2651} INFO - 0 downstream tasks scheduled from follow-on schedule check
