[2023-06-09T15:05:35.021+0000] {taskinstance.py:1103} INFO - Dependencies all met for dep_context=non-requeueable deps ti=<TaskInstance: applicants.load manual__2023-06-09T15:05:29.108361+00:00 [queued]>
[2023-06-09T15:05:35.030+0000] {taskinstance.py:1103} INFO - Dependencies all met for dep_context=requeueable deps ti=<TaskInstance: applicants.load manual__2023-06-09T15:05:29.108361+00:00 [queued]>
[2023-06-09T15:05:35.031+0000] {taskinstance.py:1308} INFO - Starting attempt 1 of 1
[2023-06-09T15:05:35.049+0000] {taskinstance.py:1327} INFO - Executing <Task(PythonOperator): load> on 2023-06-09 15:05:29.108361+00:00
[2023-06-09T15:05:35.057+0000] {standard_task_runner.py:57} INFO - Started process 8408 to run task
[2023-06-09T15:05:35.060+0000] {standard_task_runner.py:84} INFO - Running: ['***', 'tasks', 'run', 'applicants', 'load', 'manual__2023-06-09T15:05:29.108361+00:00', '--job-id', '34', '--raw', '--subdir', 'DAGS_FOLDER/etl.py', '--cfg-path', '/tmp/tmpvfqv60za']
[2023-06-09T15:05:35.061+0000] {standard_task_runner.py:85} INFO - Job 34: Subtask load
[2023-06-09T15:05:35.126+0000] {task_command.py:410} INFO - Running <TaskInstance: applicants.load manual__2023-06-09T15:05:29.108361+00:00 [running]> on host 9e894d1b1662
[2023-06-09T15:05:35.228+0000] {taskinstance.py:1547} INFO - Exporting env vars: AIRFLOW_CTX_DAG_OWNER='***' AIRFLOW_CTX_DAG_ID='applicants' AIRFLOW_CTX_TASK_ID='load' AIRFLOW_CTX_EXECUTION_DATE='2023-06-09T15:05:29.108361+00:00' AIRFLOW_CTX_TRY_NUMBER='1' AIRFLOW_CTX_DAG_RUN_ID='manual__2023-06-09T15:05:29.108361+00:00'
[2023-06-09T15:05:35.233+0000] {taskinstance.py:1824} ERROR - Task failed with exception
Traceback (most recent call last):
  File "/home/airflow/.local/lib/python3.7/site-packages/airflow/operators/python.py", line 181, in execute
    return_value = self.execute_callable()
  File "/home/airflow/.local/lib/python3.7/site-packages/airflow/operators/python.py", line 198, in execute_callable
    return self.python_callable(*self.op_args, **self.op_kwargs)
  File "/opt/airflow/dags/etl.py", line 71, in load
    DATABASE="GFA_EXAM"
pyodbc.Error: ('01000', "[01000] [unixODBC][Driver Manager]Can't open lib ''ODBC Driver 17 for SQL Server'' : file not found (0) (SQLDriverConnect)")
[2023-06-09T15:05:35.247+0000] {taskinstance.py:1350} INFO - Marking task as FAILED. dag_id=applicants, task_id=load, execution_date=20230609T150529, start_date=20230609T150535, end_date=20230609T150535
[2023-06-09T15:05:35.263+0000] {standard_task_runner.py:109} ERROR - Failed to execute job 34 for task load (('01000', "[01000] [unixODBC][Driver Manager]Can't open lib ''ODBC Driver 17 for SQL Server'' : file not found (0) (SQLDriverConnect)"); 8408)
[2023-06-09T15:05:35.273+0000] {local_task_job_runner.py:225} INFO - Task exited with return code 1
[2023-06-09T15:05:35.292+0000] {taskinstance.py:2651} INFO - 0 downstream tasks scheduled from follow-on schedule check
