[2023-06-09T13:18:42.125+0000] {taskinstance.py:1103} INFO - Dependencies all met for dep_context=non-requeueable deps ti=<TaskInstance: applicants.load manual__2023-06-09T13:18:35.395220+00:00 [queued]>
[2023-06-09T13:18:42.139+0000] {taskinstance.py:1103} INFO - Dependencies all met for dep_context=requeueable deps ti=<TaskInstance: applicants.load manual__2023-06-09T13:18:35.395220+00:00 [queued]>
[2023-06-09T13:18:42.140+0000] {taskinstance.py:1308} INFO - Starting attempt 1 of 1
[2023-06-09T13:18:42.160+0000] {taskinstance.py:1327} INFO - Executing <Task(PythonOperator): load> on 2023-06-09 13:18:35.395220+00:00
[2023-06-09T13:18:42.171+0000] {standard_task_runner.py:57} INFO - Started process 6509 to run task
[2023-06-09T13:18:42.176+0000] {standard_task_runner.py:84} INFO - Running: ['***', 'tasks', 'run', 'applicants', 'load', 'manual__2023-06-09T13:18:35.395220+00:00', '--job-id', '28', '--raw', '--subdir', 'DAGS_FOLDER/etl.py', '--cfg-path', '/tmp/tmpmwb459ef']
[2023-06-09T13:18:42.177+0000] {standard_task_runner.py:85} INFO - Job 28: Subtask load
[2023-06-09T13:18:42.240+0000] {task_command.py:410} INFO - Running <TaskInstance: applicants.load manual__2023-06-09T13:18:35.395220+00:00 [running]> on host 9e894d1b1662
[2023-06-09T13:18:42.344+0000] {taskinstance.py:1547} INFO - Exporting env vars: AIRFLOW_CTX_DAG_OWNER='***' AIRFLOW_CTX_DAG_ID='applicants' AIRFLOW_CTX_TASK_ID='load' AIRFLOW_CTX_EXECUTION_DATE='2023-06-09T13:18:35.395220+00:00' AIRFLOW_CTX_TRY_NUMBER='1' AIRFLOW_CTX_DAG_RUN_ID='manual__2023-06-09T13:18:35.395220+00:00'
[2023-06-09T13:19:12.508+0000] {taskinstance.py:1824} ERROR - Task failed with exception
Traceback (most recent call last):
  File "/home/airflow/.local/lib/python3.7/site-packages/airflow/operators/python.py", line 181, in execute
    return_value = self.execute_callable()
  File "/home/airflow/.local/lib/python3.7/site-packages/airflow/operators/python.py", line 198, in execute_callable
    return self.python_callable(*self.op_args, **self.op_kwargs)
  File "/opt/airflow/dags/etl.py", line 43, in load
    "DRIVER={ODBC Driver 18 for SQL Server};"
pyodbc.OperationalError: ('HYT00', '[HYT00] [Microsoft][ODBC Driver 18 for SQL Server]Login timeout expired (0) (SQLDriverConnect)')
[2023-06-09T13:19:12.534+0000] {taskinstance.py:1350} INFO - Marking task as FAILED. dag_id=applicants, task_id=load, execution_date=20230609T131835, start_date=20230609T131842, end_date=20230609T131912
[2023-06-09T13:19:12.564+0000] {standard_task_runner.py:109} ERROR - Failed to execute job 28 for task load (('HYT00', '[HYT00] [Microsoft][ODBC Driver 18 for SQL Server]Login timeout expired (0) (SQLDriverConnect)'); 6509)
[2023-06-09T13:19:12.630+0000] {local_task_job_runner.py:225} INFO - Task exited with return code 1
[2023-06-09T13:19:12.668+0000] {taskinstance.py:2651} INFO - 0 downstream tasks scheduled from follow-on schedule check
