[2023-06-09T09:09:15.134+0000] {taskinstance.py:1103} INFO - Dependencies all met for dep_context=non-requeueable deps ti=<TaskInstance: applicants.transform manual__2023-06-09T09:09:10.900465+00:00 [queued]>
[2023-06-09T09:09:15.144+0000] {taskinstance.py:1103} INFO - Dependencies all met for dep_context=requeueable deps ti=<TaskInstance: applicants.transform manual__2023-06-09T09:09:10.900465+00:00 [queued]>
[2023-06-09T09:09:15.144+0000] {taskinstance.py:1308} INFO - Starting attempt 1 of 1
[2023-06-09T09:09:15.162+0000] {taskinstance.py:1327} INFO - Executing <Task(PythonOperator): transform> on 2023-06-09 09:09:10.900465+00:00
[2023-06-09T09:09:15.169+0000] {standard_task_runner.py:57} INFO - Started process 2036 to run task
[2023-06-09T09:09:15.173+0000] {standard_task_runner.py:84} INFO - Running: ['***', 'tasks', 'run', 'applicants', 'transform', 'manual__2023-06-09T09:09:10.900465+00:00', '--job-id', '7', '--raw', '--subdir', 'DAGS_FOLDER/etl.py', '--cfg-path', '/tmp/tmpfeinnq60']
[2023-06-09T09:09:15.174+0000] {standard_task_runner.py:85} INFO - Job 7: Subtask transform
[2023-06-09T09:09:15.225+0000] {task_command.py:410} INFO - Running <TaskInstance: applicants.transform manual__2023-06-09T09:09:10.900465+00:00 [running]> on host 9e894d1b1662
[2023-06-09T09:09:15.299+0000] {taskinstance.py:1547} INFO - Exporting env vars: AIRFLOW_CTX_DAG_OWNER='***' AIRFLOW_CTX_DAG_ID='applicants' AIRFLOW_CTX_TASK_ID='transform' AIRFLOW_CTX_EXECUTION_DATE='2023-06-09T09:09:10.900465+00:00' AIRFLOW_CTX_TRY_NUMBER='1' AIRFLOW_CTX_DAG_RUN_ID='manual__2023-06-09T09:09:10.900465+00:00'
[2023-06-09T09:09:15.300+0000] {taskinstance.py:1824} ERROR - Task failed with exception
Traceback (most recent call last):
  File "/home/airflow/.local/lib/python3.7/site-packages/airflow/operators/python.py", line 181, in execute
    return_value = self.execute_callable()
  File "/home/airflow/.local/lib/python3.7/site-packages/airflow/operators/python.py", line 198, in execute_callable
    return self.python_callable(*self.op_args, **self.op_kwargs)
TypeError: transform() missing 1 required positional argument: 'df'
[2023-06-09T09:09:15.307+0000] {taskinstance.py:1350} INFO - Marking task as FAILED. dag_id=applicants, task_id=transform, execution_date=20230609T090910, start_date=20230609T090915, end_date=20230609T090915
[2023-06-09T09:09:15.319+0000] {standard_task_runner.py:109} ERROR - Failed to execute job 7 for task transform (transform() missing 1 required positional argument: 'df'; 2036)
[2023-06-09T09:09:15.344+0000] {local_task_job_runner.py:225} INFO - Task exited with return code 1
[2023-06-09T09:09:15.367+0000] {taskinstance.py:2651} INFO - 0 downstream tasks scheduled from follow-on schedule check
