[2023-06-13T14:56:01.351+0000] {taskinstance.py:1103} INFO - Dependencies all met for dep_context=non-requeueable deps ti=<TaskInstance: a_etldag.load_applicants manual__2023-06-13T14:55:57.269902+00:00 [queued]>
[2023-06-13T14:56:01.358+0000] {taskinstance.py:1103} INFO - Dependencies all met for dep_context=requeueable deps ti=<TaskInstance: a_etldag.load_applicants manual__2023-06-13T14:55:57.269902+00:00 [queued]>
[2023-06-13T14:56:01.358+0000] {taskinstance.py:1308} INFO - Starting attempt 1 of 1
[2023-06-13T14:56:01.390+0000] {taskinstance.py:1327} INFO - Executing <Task(PythonOperator): load_applicants> on 2023-06-13 14:55:57.269902+00:00
[2023-06-13T14:56:01.396+0000] {standard_task_runner.py:57} INFO - Started process 4215 to run task
[2023-06-13T14:56:01.399+0000] {standard_task_runner.py:84} INFO - Running: ['***', 'tasks', 'run', 'a_etldag', 'load_applicants', 'manual__2023-06-13T14:55:57.269902+00:00', '--job-id', '117', '--raw', '--subdir', 'DAGS_FOLDER/etl.py', '--cfg-path', '/tmp/tmpfb2jqzfy']
[2023-06-13T14:56:01.400+0000] {standard_task_runner.py:85} INFO - Job 117: Subtask load_applicants
[2023-06-13T14:56:01.447+0000] {task_command.py:410} INFO - Running <TaskInstance: a_etldag.load_applicants manual__2023-06-13T14:55:57.269902+00:00 [running]> on host 9e894d1b1662
[2023-06-13T14:56:01.526+0000] {taskinstance.py:1547} INFO - Exporting env vars: AIRFLOW_CTX_DAG_OWNER='***' AIRFLOW_CTX_DAG_ID='a_etldag' AIRFLOW_CTX_TASK_ID='load_applicants' AIRFLOW_CTX_EXECUTION_DATE='2023-06-13T14:55:57.269902+00:00' AIRFLOW_CTX_TRY_NUMBER='1' AIRFLOW_CTX_DAG_RUN_ID='manual__2023-06-13T14:55:57.269902+00:00'
[2023-06-13T14:56:01.616+0000] {taskinstance.py:1824} ERROR - Task failed with exception
Traceback (most recent call last):
  File "/home/airflow/.local/lib/python3.7/site-packages/airflow/operators/python.py", line 181, in execute
    return_value = self.execute_callable()
  File "/home/airflow/.local/lib/python3.7/site-packages/airflow/operators/python.py", line 198, in execute_callable
    return self.python_callable(*self.op_args, **self.op_kwargs)
  File "/opt/airflow/dags/etl.py", line 44, in load_applicants
    columns=['name_surname', 'age', 'address', 'preferred_language', 'cognitive_score', 'class_id'])
  File "/home/airflow/.local/lib/python3.7/site-packages/pandas/core/frame.py", line 717, in __init__
    typ=manager,
  File "/home/airflow/.local/lib/python3.7/site-packages/pandas/core/internals/construction.py", line 304, in ndarray_to_mgr
    values = _prep_ndarray(values, copy=copy)
  File "/home/airflow/.local/lib/python3.7/site-packages/pandas/core/internals/construction.py", line 555, in _prep_ndarray
    raise ValueError(f"Must pass 2-d input. shape={values.shape}")
ValueError: Must pass 2-d input. shape=(1, 31, 6)
[2023-06-13T14:56:01.628+0000] {taskinstance.py:1350} INFO - Marking task as FAILED. dag_id=a_etldag, task_id=load_applicants, execution_date=20230613T145557, start_date=20230613T145601, end_date=20230613T145601
[2023-06-13T14:56:01.649+0000] {standard_task_runner.py:109} ERROR - Failed to execute job 117 for task load_applicants (Must pass 2-d input. shape=(1, 31, 6); 4215)
[2023-06-13T14:56:01.691+0000] {local_task_job_runner.py:225} INFO - Task exited with return code 1
[2023-06-13T14:56:01.712+0000] {taskinstance.py:2651} INFO - 0 downstream tasks scheduled from follow-on schedule check
