[2023-06-13T14:59:30.854+0000] {taskinstance.py:1103} INFO - Dependencies all met for dep_context=non-requeueable deps ti=<TaskInstance: a_etldag.load_applicants manual__2023-06-13T14:59:28.046140+00:00 [queued]>
[2023-06-13T14:59:30.863+0000] {taskinstance.py:1103} INFO - Dependencies all met for dep_context=requeueable deps ti=<TaskInstance: a_etldag.load_applicants manual__2023-06-13T14:59:28.046140+00:00 [queued]>
[2023-06-13T14:59:30.864+0000] {taskinstance.py:1308} INFO - Starting attempt 1 of 1
[2023-06-13T14:59:30.882+0000] {taskinstance.py:1327} INFO - Executing <Task(PythonOperator): load_applicants> on 2023-06-13 14:59:28.046140+00:00
[2023-06-13T14:59:30.887+0000] {standard_task_runner.py:57} INFO - Started process 4306 to run task
[2023-06-13T14:59:30.891+0000] {standard_task_runner.py:84} INFO - Running: ['***', 'tasks', 'run', 'a_etldag', 'load_applicants', 'manual__2023-06-13T14:59:28.046140+00:00', '--job-id', '121', '--raw', '--subdir', 'DAGS_FOLDER/etl.py', '--cfg-path', '/tmp/tmp1eu7qu4n']
[2023-06-13T14:59:30.891+0000] {standard_task_runner.py:85} INFO - Job 121: Subtask load_applicants
[2023-06-13T14:59:30.931+0000] {task_command.py:410} INFO - Running <TaskInstance: a_etldag.load_applicants manual__2023-06-13T14:59:28.046140+00:00 [running]> on host 9e894d1b1662
[2023-06-13T14:59:31.006+0000] {taskinstance.py:1547} INFO - Exporting env vars: AIRFLOW_CTX_DAG_OWNER='***' AIRFLOW_CTX_DAG_ID='a_etldag' AIRFLOW_CTX_TASK_ID='load_applicants' AIRFLOW_CTX_EXECUTION_DATE='2023-06-13T14:59:28.046140+00:00' AIRFLOW_CTX_TRY_NUMBER='1' AIRFLOW_CTX_DAG_RUN_ID='manual__2023-06-13T14:59:28.046140+00:00'
[2023-06-13T14:59:31.017+0000] {taskinstance.py:1824} ERROR - Task failed with exception
Traceback (most recent call last):
  File "/home/airflow/.local/lib/python3.7/site-packages/airflow/operators/python.py", line 181, in execute
    return_value = self.execute_callable()
  File "/home/airflow/.local/lib/python3.7/site-packages/airflow/operators/python.py", line 198, in execute_callable
    return self.python_callable(*self.op_args, **self.op_kwargs)
  File "/opt/airflow/dags/etl.py", line 42, in load_applicants
    data = ti.xcom_pull(task_ids=['read_trarm'])[0]
  File "/home/airflow/.local/lib/python3.7/site-packages/airflow/models/xcom.py", line 767, in __getitem__
    raise IndexError(key) from None
IndexError: 0
[2023-06-13T14:59:31.029+0000] {taskinstance.py:1350} INFO - Marking task as FAILED. dag_id=a_etldag, task_id=load_applicants, execution_date=20230613T145928, start_date=20230613T145930, end_date=20230613T145931
[2023-06-13T14:59:31.040+0000] {standard_task_runner.py:109} ERROR - Failed to execute job 121 for task load_applicants (0; 4306)
[2023-06-13T14:59:31.062+0000] {local_task_job_runner.py:225} INFO - Task exited with return code 1
[2023-06-13T14:59:31.077+0000] {taskinstance.py:2651} INFO - 0 downstream tasks scheduled from follow-on schedule check
