[2023-06-13T13:15:53.447+0000] {taskinstance.py:1103} INFO - Dependencies all met for dep_context=non-requeueable deps ti=<TaskInstance: applicants.read_and_transform manual__2023-06-13T13:15:49.038713+00:00 [queued]>
[2023-06-13T13:15:53.455+0000] {taskinstance.py:1103} INFO - Dependencies all met for dep_context=requeueable deps ti=<TaskInstance: applicants.read_and_transform manual__2023-06-13T13:15:49.038713+00:00 [queued]>
[2023-06-13T13:15:53.455+0000] {taskinstance.py:1308} INFO - Starting attempt 1 of 1
[2023-06-13T13:15:53.471+0000] {taskinstance.py:1327} INFO - Executing <Task(PythonOperator): read_and_transform> on 2023-06-13 13:15:49.038713+00:00
[2023-06-13T13:15:53.477+0000] {standard_task_runner.py:57} INFO - Started process 2413 to run task
[2023-06-13T13:15:53.480+0000] {standard_task_runner.py:84} INFO - Running: ['***', 'tasks', 'run', 'applicants', 'read_and_transform', 'manual__2023-06-13T13:15:49.038713+00:00', '--job-id', '105', '--raw', '--subdir', 'DAGS_FOLDER/etl.py', '--cfg-path', '/tmp/tmp_jijv776']
[2023-06-13T13:15:53.481+0000] {standard_task_runner.py:85} INFO - Job 105: Subtask read_and_transform
[2023-06-13T13:15:53.524+0000] {task_command.py:410} INFO - Running <TaskInstance: applicants.read_and_transform manual__2023-06-13T13:15:49.038713+00:00 [running]> on host 9e894d1b1662
[2023-06-13T13:15:53.596+0000] {taskinstance.py:1547} INFO - Exporting env vars: AIRFLOW_CTX_DAG_OWNER='***' AIRFLOW_CTX_DAG_ID='applicants' AIRFLOW_CTX_TASK_ID='read_and_transform' AIRFLOW_CTX_EXECUTION_DATE='2023-06-13T13:15:49.038713+00:00' AIRFLOW_CTX_TRY_NUMBER='1' AIRFLOW_CTX_DAG_RUN_ID='manual__2023-06-13T13:15:49.038713+00:00'
[2023-06-13T13:15:53.864+0000] {taskinstance.py:1824} ERROR - Task failed with exception
Traceback (most recent call last):
  File "/home/airflow/.local/lib/python3.7/site-packages/airflow/operators/python.py", line 181, in execute
    return_value = self.execute_callable()
  File "/home/airflow/.local/lib/python3.7/site-packages/airflow/operators/python.py", line 198, in execute_callable
    return self.python_callable(*self.op_args, **self.op_kwargs)
  File "/opt/airflow/dags/etl.py", line 27, in read_transform
    df = df.fillna('Unknown')
AttributeError: 'function' object has no attribute 'fillna'
[2023-06-13T13:15:53.877+0000] {taskinstance.py:1350} INFO - Marking task as FAILED. dag_id=applicants, task_id=read_and_transform, execution_date=20230613T131549, start_date=20230613T131553, end_date=20230613T131553
[2023-06-13T13:15:53.890+0000] {standard_task_runner.py:109} ERROR - Failed to execute job 105 for task read_and_transform ('function' object has no attribute 'fillna'; 2413)
[2023-06-13T13:15:53.933+0000] {local_task_job_runner.py:225} INFO - Task exited with return code 1
[2023-06-13T13:15:53.952+0000] {taskinstance.py:2651} INFO - 0 downstream tasks scheduled from follow-on schedule check
